Workbook

Sheet Dashboard
A1: Retail & Distribution Co. Executive Dashboard
A2: Sales · Finance · HR · Supply Chain
A4: Company-Wide KPIs
A5: TOTAL REVENUE | D5: GROSS PROFIT | G5: GROSS MARGIN | J5: TOTAL ORDERS
A6: ='Sales Analysis'!C6 -> 1544129.2 | D6: ='Finance Analysis'!E6 -> 638866.24 | G6: ='Finance Analysis'!G6 -> 0.41373886 | J6: ='Sales Analysis'!A6 -> 400
A8: ACTIVE HEADCOUNT | D8: TOTAL PAYROLL | G8: SKUs NEEDING REORDER | J8: AR GAP (Uncollected)
A9: ='HR Analysis'!A6 -> 36 | D9: ='HR Analysis'!C6 -> 2921762 | G9: ='Supply Chain Analysis'!C6 -> 8 | J9: ='Finance Analysis'!G9 -> 275847.3
A12: Chart Data
A13: Month | B13: Revenue
A14: ='Sales Analysis'!A65 -> 2023-01 | B14: ='Sales Analysis'!B65 -> 35933.363
A15: ='Sales Analysis'!A66 -> 2023-02 | B15: ='Sales Analysis'!B66 -> 49557.449
A16: ='Sales Analysis'!A67 -> 2023-03 | B16: ='Sales Analysis'!B67 -> 37361.666
A17: ='Sales Analysis'!A68 -> 2023-04 | B17: ='Sales Analysis'!B68 -> 26172.149
A18: ='Sales Analysis'!A69 -> 2023-05 | B18: ='Sales Analysis'!B69 -> 45340.938
A19: ='Sales Analysis'!A70 -> 2023-06 | B19: ='Sales Analysis'!B70 -> 49946.831
A20: ='Sales Analysis'!A71 -> 2023-07 | B20: ='Sales Analysis'!B71 -> 52097.839
A21: ='Sales Analysis'!A72 -> 2023-08 | B21: ='Sales Analysis'!B72 -> 69113.531
A22: ='Sales Analysis'!A73 -> 2023-09 | B22: ='Sales Analysis'!B73 -> 36998.58
A23: ='Sales Analysis'!A74 -> 2023-10 | B23: ='Sales Analysis'!B74 -> 39838.62
A24: ='Sales Analysis'!A75 -> 2023-11 | B24: ='Sales Analysis'!B75 -> 34961.761
A25: ='Sales Analysis'!A76 -> 2023-12 | B25: ='Sales Analysis'!B76 -> 41076.233
... A49: ='Sales Analysis'!A100 -> 2025-12 | B49: ='Sales Analysis'!B100 -> 41335.026
A51: Category | B51: Revenue
A52: ='Sales Analysis'!A13 -> Sporting Goods | B52: ='Sales Analysis'!B13 -> 269240.84
A53: ='Sales Analysis'!A14 -> Apparel | B53: ='Sales Analysis'!B14 -> 206243
A54: ='Sales Analysis'!A15 -> Office Supplies | B54: ='Sales Analysis'!B15 -> 188788.64
A55: ='Sales Analysis'!A16 -> Electronics | B55: ='Sales Analysis'!B16 -> 185455.92
A56: ='Sales Analysis'!A17 -> Groceries | B56: ='Sales Analysis'!B17 -> 184134.4
A57: ='Sales Analysis'!A18 -> Health & Beauty | B57: ='Sales Analysis'!B18 -> 177044.39
A58: ='Sales Analysis'!A19 -> Automotive Parts | B58: ='Sales Analysis'!B19 -> 155430.56
A59: ='Sales Analysis'!A20 -> Furniture | B59: ='Sales Analysis'!B20 -> 144037.7
A60: ='Sales Analysis'!A21 -> Home & Kitchen | B60: ='Sales Analysis'!B21 -> 135507.78
A61: ='Sales Analysis'!A22 -> Toys & Games | B61: ='Sales Analysis'!B22 -> 109793.87
A63: Status | B63: Count
A64: Delivered | B64: =COUNTIF(Orders!$F$2:$F$401,"Delivered") -> 182
A65: Returned | B65: =COUNTIF(Orders!$F$2:$F$401,"Returned") -> 68
A66: Pending | B66: =COUNTIF(Orders!$F$2:$F$401,"Pending") -> 56
A67: Cancelled | B67: =COUNTIF(Orders!$F$2:$F$401,"Cancelled") -> 52
A68: Shipped | B68: =COUNTIF(Orders!$F$2:$F$401,"Shipped") -> 42
A70: Department | B70: Headcount
...

Sheet Sales Analysis
A1: Sales Performance Analysis
A4: Key Performance Indicators
A5: TOTAL ORDERS | C5: REVENUE (excl. Cancelled) | E5: AVG ORDER VALUE | G5: UNITS SOLD
A6: =COUNTA(Orders!A2:A401) -> 400 | C6: =SUMIFS(Orders!H2:H401,Orders!F2:F401,"<>Cancelled") -> 1544129.2 | E6: =C6/COUNTIFS(Orders!F2:F401,"<>Cancelled") -> 4437.1528 | G6: =SUM(OrderItems!D2:D1254) -> 6902
A8: CANCELLATION RATE | C8: RETURN RATE | E8: AVG DISCOUNT GIVEN | G8: ACTIVE CUSTOMERS
A9: =COUNTIF(Orders!F2:F401,"Cancelled")/A6 -> 0.13 | C9: =COUNTIF(Orders!F2:F401,"Returned")/A6 -> 0.17 | E9: =AVERAGE(OrderItems!F2:F1254) -> 0.073264166 | G9: =COUNTIF(Customers!I2:I61,">0") -> 60
A11: Revenue by Category | F11: Revenue by Ship Region
A12: Category | B12: Revenue | C12: Units Sold | D12: Product Count | F12: Region | G12: Revenue | H12: Orders
A13: =INDEX(Categories!$B$2:$B$11,MATCH("Sporting Goods",Categories!$B$2:$B$11,0)) -> Sporting Goods | B13: =INDEX(Categories!$E$2:$E$11,MATCH($A13,Categories!$B$2:$B$11,0)) -> 269240.84 | C13: =INDEX(Categories!$D$2:$D$11,MATCH($A13,Categories!$B$2:$B$11,0)) -> 757 | D13: =INDEX(Categories!$C$2:$C$11,MATCH($A13,Categories!$B$2:$B$11,0)) -> 10 | F13: North America | G13: =SUMIFS(Orders!$H$2:$H$401,Orders!$G$2:$G$401,$F13,Orders!$F$2:$F$401,"<>Cancelled") -> 297426.94 | H13: =COUNTIFS(Orders!$G$2:$G$401,$F13) -> 75
A14: =INDEX(Categories!$B$2:$B$11,MATCH("Apparel",Categories!$B$2:$B$11,0)) -> Apparel | B14: =INDEX(Categories!$E$2:$E$11,MATCH($A14,Categories!$B$2:$B$11,0)) -> 206243 | C14: =INDEX(Categories!$D$2:$D$11,MATCH($A14,Categories!$B$2:$B$11,0)) -> 794 | D14: =INDEX(Categories!$C$2:$C$11,MATCH($A14,Categories!$B$2:$B$11,0)) -> 10 | F14: Europe | G14: =SUMIFS(Orders!$H$2:$H$401,Orders!$G$2:$G$401,$F14,Orders!$F$2:$F$401,"<>Cancelled") -> 307118.18 | H14: =COUNTIFS(Orders!$G$2:$G$401,$F14) -> 77
A15: =INDEX(Categories!$B$2:$B$11,MATCH("Office Supplies",Categories!$B$2:$B$11,0)) -> Office Supplies | B15: =INDEX(Categories!$E$2:$E$11,MATCH($A15,Categories!$B$2:$B$11,0)) -> 188788.64 | C15: =INDEX(Categories!$D$2:$D$11,MATCH($A15,Categories!$B$2:$B$11,0)) -> 666 | D15: =INDEX(Categories!$C$2:$C$11,MATCH($A15,Categories!$B$2:$B$11,0)) -> 10 | F15: Asia Pacific | G15: =SUMIFS(Orders!$H$2:$H$401,Orders!$G$2:$G$401,$F15,Orders!$F$2:$F$401,"<>Cancelled") -> 298341.04 | H15: =COUNTIFS(Orders!$G$2:$G$401,$F15) -> 79
A16: =INDEX(Categories!$B$2:$B$11,MATCH("Electronics",Categories!$B$2:$B$11,0)) -> Electronics | B16: =INDEX(Categories!$E$2:$E$11,MATCH($A16,Categories!$B$2:$B$11,0)) -> 185455.92 | C16: =INDEX(Categories!$D$2:$D$11,MATCH($A16,Categories!$B$2:$B$11,0)) -> 711 | D16: =INDEX(Categories!$C$2:$C$11,MATCH($A16,Categories!$B$2:$B$11,0)) -> 10 | F16: Middle East | G16: =SUMIFS(Orders!$H$2:$H$401,Orders!$G$2:$G$401,$F16,Orders!$F$2:$F$401,"<>Cancelled") -> 310171.62 | H16: =COUNTIFS(Orders!$G$2:$G$401,$F16) -> 88
A17: =INDEX(Categories!$B$2:$B$11,MATCH("Groceries",Categories!$B$2:$B$11,0)) -> Groceries | B17: =INDEX(Categories!$E$2:$E$11,MATCH($A17,Categories!$B$2:$B$11,0)) -> 184134.4 | C17: =INDEX(Categories!$D$2:$D$11,MATCH($A17,Categories!$B$2:$B$11,0)) -> 710 | D17: =INDEX(Categories!$C$2:$C$11,MATCH($A17,Categories!$B$2:$B$11,0)) -> 10 | F17: Latin America | G17: =SUMIFS(Orders!$H$2:$H$401,Orders!$G$2:$G$401,$F17,Orders!$F$2:$F$401,"<>Cancelled") -> 331071.38 | H17: =COUNTIFS(Orders!$G$2:$G$401,$F17) -> 81
A18: =INDEX(Categories!$B$2:$B$11,MATCH("Health & Beauty",Categories!$B$2:$B$11,0)) -> Health & Beauty | B18: =INDEX(Categories!$E$2:$E$11,MATCH($A18,Categories!$B$2:$B$11,0)) -> 177044.39 | C18: =INDEX(Categories!$D$2:$D$11,MATCH($A18,Categories!$B$2:$B$11,0)) -> 638 | D18: =INDEX(Categories!$C$2:$C$11,MATCH($A18,Categories!$B$2:$B$11,0)) -> 10
A19: =INDEX(Categories!$B$2:$B$11,MATCH("Automotive Parts",Categories!$B$2:$B$11,0)) -> Automotive Parts | B19: =INDEX(Categories!$E$2:$E$11,MATCH($A19,Categories!$B$2:$B$11,0)) -> 155430.56 | C19: =INDEX(Categories!$D$2:$D$11,MATCH($A19,Categories!$B$2:$B$11,0)) -> 654 | D19: =INDEX(Categories!$C$2:$C$11,MATCH($A19,Categories!$B$2:$B$11,0)) -> 10
A20: =INDEX(Categories!$B$2:$B$11,MATCH("Furniture",Categories!$B$2:$B$11,0)) -> Furniture | B20: =INDEX(Categories!$E$2:$E$11,MATCH($A20,Categories!$B$2:$B$11,0)) -> 144037.7 | C20: =INDEX(Categories!$D$2:$D$11,MATCH($A20,Categories!$B$2:$B$11,0)) -> 621 | D20: =INDEX(Categories!$C$2:$C$11,MATCH($A20,Categories!$B$2:$B$11,0)) -> 10
A21: =INDEX(Categories!$B$2:$B$11,MATCH("Home & Kitchen",Categories!$B$2:$B$11,0)) -> Home & Kitchen | B21: =INDEX(Categories!$E$2:$E$11,MATCH($A21,Categories!$B$2:$B$11,0)) -> 135507.78 | C21: =INDEX(Categories!$D$2:$D$11,MATCH($A21,Categories!$B$2:$B$11,0)) -> 710 | D21: =INDEX(Categories!$C$2:$C$11,MATCH($A21,Categories!$B$2:$B$11,0)) -> 10
A22: =INDEX(Categories!$B$2:$B$11,MATCH("Toys & Games",Categories!$B$2:$B$11,0)) -> Toys & Games | B22: =INDEX(Categories!$E$2:$E$11,MATCH($A22,Categories!$B$2:$B$11,0)) -> 109793.87 | C22: =INDEX(Categories!$D$2:$D$11,MATCH($A22,Categories!$B$2:$B$11,0)) -> 641 | D22: =INDEX(Categories!$C$2:$C$11,MATCH($A22,Categories!$B$2:$B$11,0)) -> 10
A24: Revenue by Customer Segment
A25: Segment | B25: Revenue | C25: Orders
A26: Corporate | B26: =SUMIFS(Orders!$H$2:$H$401,Orders!$L$2:$L$401,$A26,Orders!$F$2:$F$401,"<>Cancelled") -> 457649.96 | C26: =COUNTIFS(Orders!$L$2:$L$401,$A26) -> 113
A27: Small Business | B27: =SUMIFS(Orders!$H$2:$H$401,Orders!$L$2:$L$401,$A27,Orders!$F$2:$F$401,"<>Cancelled") -> 483432.45 | C27: =COUNTIFS(Orders!$L$2:$L$401,$A27) -> 126
A28: Consumer | B28: =SUMIFS(Orders!$H$2:$H$401,Orders!$L$2:$L$401,$A28,Orders!$F$2:$F$401,"<>Cancelled") -> 603046.76 | C28: =COUNTIFS(Orders!$L$2:$L$401,$A28) -> 161
A30: Top 10 Products by Revenue
A31: Product ID | B31: Product Name | C31: Category | D31: Revenue | E31: Units Sold
A32: 36 | B32: =INDEX(Products!$B$2:$B$101,MATCH($A32,Products!$A$2:$A$101,0)) -> Rain Jacket | C32: =INDEX(Products!$J$2:$J$101,MATCH($A32,Products!$A$2:$A$101,0)) -> Apparel | D32: =INDEX(Products!$O$2:$O$101,MATCH($A32,Products!$A$2:$A$101,0)) -> 41485.567 | E32: =INDEX(Products!$N$2:$N$101,MATCH($A32,Products!$A$2:$A$101,0)) -> 95
A33: 51 | B33: =INDEX(Products!$B$2:$B$101,MATCH($A33,Products!$A$2:$A$101,0)) -> Yoga Mat | C33: =INDEX(Products!$J$2:$J$101,MATCH($A33,Products!$A$2:$A$101,0)) -> Sporting Goods | D33: =INDEX(Products!$O$2:$O$101,MATCH($A33,Products!$A$2:$A$101,0)) -> 41242.635 | E33: =INDEX(Products!$N$2:$N$101,MATCH($A33,Products!$A$2:$A$101,0)) -> 104
A34: 50 | B34: =INDEX(Products!$B$2:$B$101,MATCH($A34,Products!$A$2:$A$101,0)) -> Electric Kettle | C34: =INDEX(Products!$J$2:$J$101,MATCH($A34,Products!$A$2:$A$101,0)) -> Home & Kitchen | D34: =INDEX(Products!$O$2:$O$101,MATCH($A34,Products!$A$2:$A$101,0)) -> 39460.8 | E34: =INDEX(Products!$N$2:$N$101,MATCH($A34,Products!$A$2:$A$101,0)) -> 105
A35: 55 | B35: =INDEX(Products!$B$2:$B$101,MATCH($A35,Products!$A$2:$A$101,0)) -> Camping Tent | C35: =INDEX(Products!$J$2:$J$101,MATCH($A35,Products!$A$2:$A$101,0)) -> Sporting Goods | D35: =INDEX(Products!$O$2:$O$101,MATCH($A35,Products!$A$2:$A$101,0)) -> 37089.374 | E35: =INDEX(Products!$N$2:$N$101,MATCH($A35,Products!$A$2:$A$101,0)) -> 106
A36: 53 | B36: =INDEX(Products!$B$2:$B$101,MATCH($A36,Products!$A$2:$A$101,0)) -> Soccer Ball | C36: =INDEX(Products!$J$2:$J$101,MATCH($A36,Products!$A$2:$A$101,0)) -> Sporting Goods | D36: =INDEX(Products!$O$2:$O$101,MATCH($A36,Products!$A$2:$A$101,0)) -> 36659.1 | E36: =INDEX(Products!$N$2:$N$101,MATCH($A36,Products!$A$2:$A$101,0)) -> 74
A37: 34 | B37: =INDEX(Products!$B$2:$B$101,MATCH($A37,Products!$A$2:$A$101,0)) -> Wool Sweater | C37: =INDEX(Products!$J$2:$J$101,MATCH($A37,Products!$A$2:$A$101,0)) -> Apparel | D37: =INDEX(Products!$O$2:$O$101,MATCH($A37,Products!$A$2:$A$101,0)) -> 35994.425 | E37: =INDEX(Products!$N$2:$N$101,MATCH($A37,Products!$A$2:$A$101,0)) -> 113
A38: 11 | B38: =INDEX(Products!$B$2:$B$101,MATCH($A38,Products!$A$2:$A$101,0)) -> Stapler | C38: =INDEX(Products!$J$2:$J$101,MATCH($A38,Products!$A$2:$A$101,0)) -> Office Supplies | D38: =INDEX(Products!$O$2:$O$101,MATCH($A38,Products!$A$2:$A$101,0)) -> 34118.78 | E38: =INDEX(Products!$N$2:$N$101,MATCH($A38,Products!$A$2:$A$101,0)) -> 87
A39: 72 | B39: =INDEX(Products!$B$2:$B$101,MATCH($A39,Products!$A$2:$A$101,0)) -> Hair Dryer | C39: =INDEX(Products!$J$2:$J$101,MATCH($A39,Products!$A$2:$A$101,0)) -> Health & Beauty | D39: =INDEX(Products!$O$2:$O$101,MATCH($A39,Products!$A$2:$A$101,0)) -> 33261.105 | E39: =INDEX(Products!$N$2:$N$101,MATCH($A39,Products!$A$2:$A$101,0)) -> 69
A40: 33 | B40: =INDEX(Products!$B$2:$B$101,MATCH($A40,Products!$A$2:$A$101,0)) -> Running Shoes | C40: =INDEX(Products!$J$2:$J$101,MATCH($A40,Products!$A$2:$A$101,0)) -> Apparel | D40: =INDEX(Products!$O$2:$O$101,MATCH($A40,Products!$A$2:$A$101,0)) -> 32684.583 | E40: =INDEX(Products!$N$2:$N$101,MATCH($A40,Products!$A$2:$A$101,0)) -> 81
A41: 58 | B41: =INDEX(Products!$B$2:$B$101,MATCH($A41,Products!$A$2:$A$101,0)) -> Water Bottle | C41: =INDEX(Products!$J$2:$J$101,MATCH($A41,Products!$A$2:$A$101,0)) -> Sporting Goods | D41: =INDEX(Products!$O$2:$O$101,MATCH($A41,Products!$A$2:$A$101,0)) -> 31433.695 | E41: =INDEX(Products!$N$2:$N$101,MATCH($A41,Products!$A$2:$A$101,0)) -> 85
A43: Top 10 Customers by Revenue
A44: Customer ID | B44: Company | C44: Segment | D44: Revenue
A45: 40 | B45: =INDEX(Customers!$B$2:$B$61,MATCH($A45,Customers!$A$2:$A$61,0)) -> Union Traders | C45: =INDEX(Customers!$G$2:$G$61,MATCH($A45,Customers!$A$2:$A$61,0)) -> Corporate | D45: =INDEX(Customers!$J$2:$J$61,MATCH($A45,Customers!$A$2:$A$61,0)) -> 81483.696
A46: 56 | B46: =INDEX(Customers!$B$2:$B$61,MATCH($A46,Customers!$A$2:$A$61,0)) -> Coastal Ventures | C46: =INDEX(Customers!$G$2:$G$61,MATCH($A46,Customers!$A$2:$A$61,0)) -> Consumer | D46: =INDEX(Customers!$J$2:$J$61,MATCH($A46,Customers!$A$2:$A$61,0)) -> 61687.656
A47: 31 | B47: =INDEX(Customers!$B$2:$B$61,MATCH($A47,Customers!$A$2:$A$61,0)) -> Silver Ventures | C47: =INDEX(Customers!$G$2:$G$61,MATCH($A47,Customers!$A$2:$A$61,0)) -> Consumer | D47: =INDEX(Customers!$J$2:$J$61,MATCH($A47,Customers!$A$2:$A$61,0)) -> 59497.623
...

Sheet Finance Analysis
A1: Finance Analysis
A2: Revenue, cost, margin, payments and payroll vs. budget
A4: Key Performance Indicators
A5: GROSS REVENUE (excl. Cancelled) | C5: TOTAL COGS | E5: GROSS PROFIT | G5: GROSS MARGIN %
A6: =SUMIFS(Orders!H2:H401,Orders!F2:F401,"<>Cancelled") -> 1544129.2 | C6: =SUMIFS(Orders!I2:I401,Orders!F2:F401,"<>Cancelled") -> 905262.92 | E6: =A6-C6 -> 638866.24 | G6: =E6/A6 -> 0.41373886
A8: CASH COLLECTED (Completed) | C8: REFUNDED | E8: PENDING PAYMENTS | G8: AR GAP (Revenue-Collected)
A9: =SUMIFS(Payments!D2:D349,Payments!F2:F349,"Completed") -> 1268281.9 | C9: =SUMIFS(Payments!D2:D349,Payments!F2:F349,"Refunded") -> 144617.54 | E9: =SUMIFS(Payments!D2:D349,Payments!F2:F349,"Pending") -> 131229.75 | G9: =A6-A9 -> 275847.3
A11: Payments by Status | F11: Payments by Method
A12: Status | B12: Count | C12: Total Amount | D12: % of Payments | F12: Method | G12: Count | H12: Total Amount
A13: Completed | B13: =COUNTIF(Payments!$F$2:$F$349,$A13) -> 284 | C13: =SUMIF(Payments!$F$2:$F$349,$A13,Payments!$D$2:$D$349) -> 1268281.9 | D13: =B13/COUNTA(Payments!$A$2:$A$349) -> 0.81609195 | F13: Credit Card | G13: =COUNTIF(Payments!$E$2:$E$349,$F13) -> 92 | H13: =SUMIF(Payments!$E$2:$E$349,$F13,Payments!$D$2:$D$349) -> 438262.21
A14: Refunded | B14: =COUNTIF(Payments!$F$2:$F$349,$A14) -> 33 | C14: =SUMIF(Payments!$F$2:$F$349,$A14,Payments!$D$2:$D$349) -> 144617.54 | D14: =B14/COUNTA(Payments!$A$2:$A$349) -> 0.094827586 | F14: Bank Transfer | G14: =COUNTIF(Payments!$E$2:$E$349,$F14) -> 90 | H14: =SUMIF(Payments!$E$2:$E$349,$F14,Payments!$D$2:$D$349) -> 416570.46
A15: Pending | B15: =COUNTIF(Payments!$F$2:$F$349,$A15) -> 31 | C15: =SUMIF(Payments!$F$2:$F$349,$A15,Payments!$D$2:$D$349) -> 131229.75 | D15: =B15/COUNTA(Payments!$A$2:$A$349) -> 0.08908046 | F15: PayPal | G15: =COUNTIF(Payments!$E$2:$E$349,$F15) -> 84 | H15: =SUMIF(Payments!$E$2:$E$349,$F15,Payments!$D$2:$D$349) -> 373894.6
F16: Check | G16: =COUNTIF(Payments!$E$2:$E$349,$F16) -> 82 | H16: =SUMIF(Payments!$E$2:$E$349,$F16,Payments!$D$2:$D$349) -> 315401.89
A17: Department Budget vs. Payroll Cost
A18: Department | B18: Budget | C18: Headcount | D18: Payroll Cost | E18: Variance | F18: Utilization %
A19: =Departments!B2 -> Sales | B19: =Departments!C2 -> 500000 | C19: =Departments!D2 -> 0 | D19: =Departments!E2 -> 0 | E19: =Departments!F2 -> 500000 | F19: =Departments!G2 -> 0
A20: =Departments!B3 -> Marketing | B20: =Departments!C3 -> 250000 | C20: =Departments!D3 -> 4 | D20: =Departments!E3 -> 355891.84 | E20: =Departments!F3 -> -105891.84 | F20: =Departments!G3 -> 1.4235674
A21: =Departments!B4 -> Finance | B21: =Departments!C4 -> 300000 | C21: =Departments!D4 -> 6 | D21: =Departments!E4 -> 458531.52 | E21: =Departments!F4 -> -158531.52 | F21: =Departments!G4 -> 1.5284384
A22: =Departments!B5 -> Operations | B22: =Departments!C5 -> 450000 | C22: =Departments!D5 -> 4 | D22: =Departments!E5 -> 338462.72 | E22: =Departments!F5 -> 111537.28 | F22: =Departments!G5 -> 0.75213938
A23: =Departments!B6 -> Human Resources | B23: =Departments!C6 -> 150000 | C23: =Departments!D6 -> 6 | D23: =Departments!E6 -> 477814.43 | E23: =Departments!F6 -> -327814.43 | F23: =Departments!G6 -> 3.1854295
A24: =Departments!B7 -> IT | B24: =Departments!C7 -> 350000 | C24: =Departments!D7 -> 6 | D24: =Departments!E7 -> 431307.33 | E24: =Departments!F7 -> -81307.33 | F24: =Departments!G7 -> 1.2323067
A25: =Departments!B8 -> Customer Support | B25: =Departments!C8 -> 200000 | C25: =Departments!D8 -> 6 | D25: =Departments!E8 -> 508330.64 | E25: =Departments!F8 -> -308330.64 | F25: =Departments!G8 -> 2.5416532
A27: Category Profitability
A28: Category | B28: Revenue | C28: Inventory Value | D28: Est. COGS on Sales | E28: Est. Margin %
A29: =INDEX(Categories!$B$2:$B$11,MATCH("Sporting Goods",Categories!$B$2:$B$11,0)) -> Sporting Goods | B29: =INDEX(Categories!$E$2:$E$11,MATCH($A29,Categories!$B$2:$B$11,0)) -> 269240.84 | C29: =INDEX(Categories!$F$2:$F$11,MATCH($A29,Categories!$B$2:$B$11,0)) -> 517487.33 | D29: =SUMIFS(OrderItems!$K$2:$K$1254,OrderItems!$I$2:$I$1254,$A29) -> 149778.88 | E29: =IFERROR((B29-D29)/B29,0) -> 0.44369925
A30: =INDEX(Categories!$B$2:$B$11,MATCH("Apparel",Categories!$B$2:$B$11,0)) -> Apparel | B30: =INDEX(Categories!$E$2:$E$11,MATCH($A30,Categories!$B$2:$B$11,0)) -> 206243 | C30: =INDEX(Categories!$F$2:$F$11,MATCH($A30,Categories!$B$2:$B$11,0)) -> 342078.09 | D30: =SUMIFS(OrderItems!$K$2:$K$1254,OrderItems!$I$2:$I$1254,$A30) -> 121515.51 | E30: =IFERROR((B30-D30)/B30,0) -> 0.4108139
A31: =INDEX(Categories!$B$2:$B$11,MATCH("Office Supplies",Categories!$B$2:$B$11,0)) -> Office Supplies | B31: =INDEX(Categories!$E$2:$E$11,MATCH($A31,Categories!$B$2:$B$11,0)) -> 188788.64 | C31: =INDEX(Categories!$F$2:$F$11,MATCH($A31,Categories!$B$2:$B$11,0)) -> 494090.55 | D31: =SUMIFS(OrderItems!$K$2:$K$1254,OrderItems!$I$2:$I$1254,$A31) -> 117283.98 | E31: =IFERROR((B31-D31)/B31,0) -> 0.37875509
A32: =INDEX(Categories!$B$2:$B$11,MATCH("Electronics",Categories!$B$2:$B$11,0)) -> Electronics | B32: =INDEX(Categories!$E$2:$E$11,MATCH($A32,Categories!$B$2:$B$11,0)) -> 185455.92 | C32: =INDEX(Categories!$F$2:$F$11,MATCH($A32,Categories!$B$2:$B$11,0)) -> 474429.85 | D32: =SUMIFS(OrderItems!$K$2:$K$1254,OrderItems!$I$2:$I$1254,$A32) -> 107693.74 | E32: =IFERROR((B32-D32)/B32,0) -> 0.41930276
A33: =INDEX(Categories!$B$2:$B$11,MATCH("Groceries",Categories!$B$2:$B$11,0)) -> Groceries | B33: =INDEX(Categories!$E$2:$E$11,MATCH($A33,Categories!$B$2:$B$11,0)) -> 184134.4 | C33: =INDEX(Categories!$F$2:$F$11,MATCH($A33,Categories!$B$2:$B$11,0)) -> 343753.31 | D33: =SUMIFS(OrderItems!$K$2:$K$1254,OrderItems!$I$2:$I$1254,$A33) -> 105551.09 | E33: =IFERROR((B33-D33)/B33,0) -> 0.42677148
A34: =INDEX(Categories!$B$2:$B$11,MATCH("Health & Beauty",Categories!$B$2:$B$11,0)) -> Health & Beauty | B34: =INDEX(Categories!$E$2:$E$11,MATCH($A34,Categories!$B$2:$B$11,0)) -> 177044.39 | C34: =INDEX(Categories!$F$2:$F$11,MATCH($A34,Categories!$B$2:$B$11,0)) -> 466264.94 | D34: =SUMIFS(OrderItems!$K$2:$K$1254,OrderItems!$I$2:$I$1254,$A34) -> 106106.16 | E34: =IFERROR((B34-D34)/B34,0) -> 0.40068048
A35: =INDEX(Categories!$B$2:$B$11,MATCH("Automotive Parts",Categories!$B$2:$B$11,0)) -> Automotive Parts | B35: =INDEX(Categories!$E$2:$E$11,MATCH($A35,Categories!$B$2:$B$11,0)) -> 155430.56 | C35: =INDEX(Categories!$F$2:$F$11,MATCH($A35,Categories!$B$2:$B$11,0)) -> 359871.16 | D35: =SUMIFS(OrderItems!$K$2:$K$1254,OrderItems!$I$2:$I$1254,$A35) -> 91834.81 | E35: =IFERROR((B35-D35)/B35,0) -> 0.40915859
A36: =INDEX(Categories!$B$2:$B$11,MATCH("Furniture",Categories!$B$2:$B$11,0)) -> Furniture | B36: =INDEX(Categories!$E$2:$E$11,MATCH($A36,Categories!$B$2:$B$11,0)) -> 144037.7 | C36: =INDEX(Categories!$F$2:$F$11,MATCH($A36,Categories!$B$2:$B$11,0)) -> 374937.3 | D36: =SUMIFS(OrderItems!$K$2:$K$1254,OrderItems!$I$2:$I$1254,$A36) -> 86135.48 | E36: =IFERROR((B36-D36)/B36,0) -> 0.4019935
A37: =INDEX(Categories!$B$2:$B$11,MATCH("Home & Kitchen",Categories!$B$2:$B$11,0)) -> Home & Kitchen | B37: =INDEX(Categories!$E$2:$E$11,MATCH($A37,Categories!$B$2:$B$11,0)) -> 135507.78 | C37: =INDEX(Categories!$F$2:$F$11,MATCH($A37,Categories!$B$2:$B$11,0)) -> 246239.51 | D37: =SUMIFS(OrderItems!$K$2:$K$1254,OrderItems!$I$2:$I$1254,$A37) -> 79897.14 | E37: =IFERROR((B37-D37)/B37,0) -> 0.41038706
A38: =INDEX(Categories!$B$2:$B$11,MATCH("Toys & Games",Categories!$B$2:$B$11,0)) -> Toys & Games | B38: =INDEX(Categories!$E$2:$E$11,MATCH($A38,Categories!$B$2:$B$11,0)) -> 109793.87 | C38: =INDEX(Categories!$F$2:$F$11,MATCH($A38,Categories!$B$2:$B$11,0)) -> 199556.26 | D38: =SUMIFS(OrderItems!$K$2:$K$1254,OrderItems!$I$2:$I$1254,$A38) -> 63061.95 | E38: =IFERROR((B38-D38)/B38,0) -> 0.42563322
A40: Monthly Cash Collected (Completed Payments)
A41: Month | B41: Cash Collected | C41: Payment Count
A42: 2023-01 | B42: =SUMIFS(Payments!$D$2:$D$349,Payments!$H$2:$H$349,$A42,Payments!$F$2:$F$349,"Completed") -> 13815.4 | C42: =COUNTIFS(Payments!$H$2:$H$349,$A42,Payments!$F$2:$F$349,"Completed") -> 3
A43: 2023-02 | B43: =SUMIFS(Payments!$D$2:$D$349,Payments!$H$2:$H$349,$A43,Payments!$F$2:$F$349,"Completed") -> 37838.82 | C43: =COUNTIFS(Payments!$H$2:$H$349,$A43,Payments!$F$2:$F$349,"Completed") -> 7
A44: 2023-03 | B44: =SUMIFS(Payments!$D$2:$D$349,Payments!$H$2:$H$349,$A44,Payments!$F$2:$F$349,"Completed") -> 29759.34 | C44: =COUNTIFS(Payments!$H$2:$H$349,$A44,Payments!$F$2:$F$349,"Completed") -> 7
A45: 2023-04 | B45: =SUMIFS(Payments!$D$2:$D$349,Payments!$H$2:$H$349,$A45,Payments!$F$2:$F$349,"Completed") -> 25786.11 | C45: =COUNTIFS(Payments!$H$2:$H$349,$A45,Payments!$F$2:$F$349,"Completed") -> 4
...

Sheet HR Analysis
A1: Human Resources Analysis
A2: Headcount, compensation, tenure and org structure
A4: Key Performance Indicators
A5: TOTAL HEADCOUNT | C5: TOTAL PAYROLL (Annual) | E5: AVERAGE SALARY | G5: AVG TENURE (Years)
A6: =COUNTA(Employees!A2:A37) -> 36 | C6: =SUM(Employees!I2:I37) -> 2921762 | E6: =AVERAGE(Employees!I2:I37) -> 81160.055 | G6: =AVERAGE(Employees!L2:L37) -> 6.6777778
A8: TOTAL DEPT BUDGET | C8: PAYROLL / BUDGET % | E8: MEDIAN SALARY | G8: HEADCOUNT W/ DIRECT REPORTS
A9: =SUM(Departments!C2:C8) -> 2200000 | C9: =B6/A9 -> 0 | E9: =MEDIAN(Employees!I2:I37) -> 80304.775 | G9: =COUNTIF(Employees!N2:N37,">0") -> 7
A11: Headcount & Compensation by Department
A12: Department | B12: Headcount | C12: Avg Salary | D12: Min Salary | E12: Max Salary | F12: Total Payroll
A13: =Departments!B2 -> Sales | B13: =Departments!D2 -> 0 | C13: =IFERROR(AVERAGEIF(Employees!$E$2:$E$37,Departments!A2,Employees!$I$2:$I$37),0) -> 0 | D13: =IFERROR(minifs(Employees!$I$2:$I$37,Employees!$E$2:$E$37,Departments!A2),0) -> 0 | E13: =IFERROR(maxifs(Employees!$I$2:$I$37,Employees!$E$2:$E$37,Departments!A2),0) -> 0 | F13: =Departments!E2 -> 0
A14: =Departments!B3 -> Marketing | B14: =Departments!D3 -> 4 | C14: =IFERROR(AVERAGEIF(Employees!$E$2:$E$37,Departments!A3,Employees!$I$2:$I$37),0) -> 88972.96 | D14: =IFERROR(minifs(Employees!$I$2:$I$37,Employees!$E$2:$E$37,Departments!A3),0) -> 0 | E14: =IFERROR(maxifs(Employees!$I$2:$I$37,Employees!$E$2:$E$37,Departments!A3),0) -> 0 | F14: =Departments!E3 -> 355891.84
A15: =Departments!B4 -> Finance | B15: =Departments!D4 -> 6 | C15: =IFERROR(AVERAGEIF(Employees!$E$2:$E$37,Departments!A4,Employees!$I$2:$I$37),0) -> 76421.92 | D15: =IFERROR(minifs(Employees!$I$2:$I$37,Employees!$E$2:$E$37,Departments!A4),0) -> 0 | E15: =IFERROR(maxifs(Employees!$I$2:$I$37,Employees!$E$2:$E$37,Departments!A4),0) -> 0 | F15: =Departments!E4 -> 458531.52
A16: =Departments!B5 -> Operations | B16: =Departments!D5 -> 4 | C16: =IFERROR(AVERAGEIF(Employees!$E$2:$E$37,Departments!A5,Employees!$I$2:$I$37),0) -> 84615.68 | D16: =IFERROR(minifs(Employees!$I$2:$I$37,Employees!$E$2:$E$37,Departments!A5),0) -> 0 | E16: =IFERROR(maxifs(Employees!$I$2:$I$37,Employees!$E$2:$E$37,Departments!A5),0) -> 0 | F16: =Departments!E5 -> 338462.72
A17: =Departments!B6 -> Human Resources | B17: =Departments!D6 -> 6 | C17: =IFERROR(AVERAGEIF(Employees!$E$2:$E$37,Departments!A6,Employees!$I$2:$I$37),0) -> 79635.738 | D17: =IFERROR(minifs(Employees!$I$2:$I$37,Employees!$E$2:$E$37,Departments!A6),0) -> 0 | E17: =IFERROR(maxifs(Employees!$I$2:$I$37,Employees!$E$2:$E$37,Departments!A6),0) -> 0 | F17: =Departments!E6 -> 477814.43
A18: =Departments!B7 -> IT | B18: =Departments!D7 -> 6 | C18: =IFERROR(AVERAGEIF(Employees!$E$2:$E$37,Departments!A7,Employees!$I$2:$I$37),0) -> 71884.555 | D18: =IFERROR(minifs(Employees!$I$2:$I$37,Employees!$E$2:$E$37,Departments!A7),0) -> 0 | E18: =IFERROR(maxifs(Employees!$I$2:$I$37,Employees!$E$2:$E$37,Departments!A7),0) -> 0 | F18: =Departments!E7 -> 431307.33
A19: =Departments!B8 -> Customer Support | B19: =Departments!D8 -> 6 | C19: =IFERROR(AVERAGEIF(Employees!$E$2:$E$37,Departments!A8,Employees!$I$2:$I$37),0) -> 84721.773 | D19: =IFERROR(minifs(Employees!$I$2:$I$37,Employees!$E$2:$E$37,Departments!A8),0) -> 0 | E19: =IFERROR(maxifs(Employees!$I$2:$I$37,Employees!$E$2:$E$37,Departments!A8),0) -> 0 | F19: =Departments!E8 -> 508330.64
A21: Headcount by Region
A22: Region | B22: Headcount | C22: Avg Salary
A23: North America | B23: =COUNTIF(Employees!$J$2:$J$37,$A23) -> 8 | C23: =IFERROR(AVERAGEIF(Employees!$J$2:$J$37,$A23,Employees!$I$2:$I$37),0) -> 74055.154
A24: Europe | B24: =COUNTIF(Employees!$J$2:$J$37,$A24) -> 6 | C24: =IFERROR(AVERAGEIF(Employees!$J$2:$J$37,$A24,Employees!$I$2:$I$37),0) -> 79553.392
A25: Asia Pacific | B25: =COUNTIF(Employees!$J$2:$J$37,$A25) -> 11 | C25: =IFERROR(AVERAGEIF(Employees!$J$2:$J$37,$A25,Employees!$I$2:$I$37),0) -> 85148.41
A26: Middle East | B26: =COUNTIF(Employees!$J$2:$J$37,$A26) -> 6 | C26: =IFERROR(AVERAGEIF(Employees!$J$2:$J$37,$A26,Employees!$I$2:$I$37),0) -> 94548.898
A27: Latin America | B27: =COUNTIF(Employees!$J$2:$J$37,$A27) -> 5 | C27: =IFERROR(AVERAGEIF(Employees!$J$2:$J$37,$A27,Employees!$I$2:$I$37),0) -> 69614.9
A29: Tenure Distribution
A30: Tenure Band | B30: Headcount
A31: 0-2 years | B31: =COUNTIFS(Employees!$L$2:$L$37,"<2") -> 1
A32: 2-5 years | B32: =COUNTIFS(Employees!$L$2:$L$37,">=2",Employees!$L$2:$L$37,"<5") -> 11
A33: 5-8 years | B33: =COUNTIFS(Employees!$L$2:$L$37,">=5",Employees!$L$2:$L$37,"<8") -> 9
A34: 8+ years | B34: =COUNTIFS(Employees!$L$2:$L$37,">=8") -> 15
A36: Manager Span of Control
A37: Employee ID | B37: Manager Name | C37: Department | D37: Direct Reports
A38: 1 | B38: =INDEX(Employees!$B$2:$B$37,MATCH($A38,Employees!$A$2:$A$37,0))&" "&INDEX(Employees!$C$2:$C$37,MATCH($A38,Employees!$A$2:$A$37,0)) -> Daniel Brown | C38: =INDEX(Employees!$K$2:$K$37,MATCH($A38,Employees!$A$2:$A$37,0)) -> Unassigned | D38: =INDEX(Employees!$N$2:$N$37,MATCH($A38,Employees!$A$2:$A$37,0)) -> 3
A39: 2 | B39: =INDEX(Employees!$B$2:$B$37,MATCH($A39,Employees!$A$2:$A$37,0))&" "&INDEX(Employees!$C$2:$C$37,MATCH($A39,Employees!$A$2:$A$37,0)) -> Linda Jones | C39: =INDEX(Employees!$K$2:$K$37,MATCH($A39,Employees!$A$2:$A$37,0)) -> Marketing | D39: =INDEX(Employees!$N$2:$N$37,MATCH($A39,Employees!$A$2:$A$37,0)) -> 3
A40: 3 | B40: =INDEX(Employees!$B$2:$B$37,MATCH($A40,Employees!$A$2:$A$37,0))&" "&INDEX(Employees!$C$2:$C$37,MATCH($A40,Employees!$A$2:$A$37,0)) -> John Jackson | C40: =INDEX(Employees!$K$2:$K$37,MATCH($A40,Employees!$A$2:$A$37,0)) -> Finance | D40: =INDEX(Employees!$N$2:$N$37,MATCH($A40,Employees!$A$2:$A$37,0)) -> 5
A41: 4 | B41: =INDEX(Employees!$B$2:$B$37,MATCH($A41,Employees!$A$2:$A$37,0))&" "&INDEX(Employees!$C$2:$C$37,MATCH($A41,Employees!$A$2:$A$37,0)) -> Michael Davis | C41: =INDEX(Employees!$K$2:$K$37,MATCH($A41,Employees!$A$2:$A$37,0)) -> Operations | D41: =INDEX(Employees!$N$2:$N$37,MATCH($A41,Employees!$A$2:$A$37,0)) -> 3
A42: 5 | B42: =INDEX(Employees!$B$2:$B$37,MATCH($A42,Employees!$A$2:$A$37,0))&" "&INDEX(Employees!$C$2:$C$37,MATCH($A42,Employees!$A$2:$A$37,0)) -> Michael Moore | C42: =INDEX(Employees!$K$2:$K$37,MATCH($A42,Employees!$A$2:$A$37,0)) -> Human Resources | D42: =INDEX(Employees!$N$2:$N$37,MATCH($A42,Employees!$A$2:$A$37,0)) -> 5
A43: 6 | B43: =INDEX(Employees!$B$2:$B$37,MATCH($A43,Employees!$A$2:$A$37,0))&" "&INDEX(Employees!$C$2:$C$37,MATCH($A43,Employees!$A$2:$A$37,0)) -> William Smith | C43: =INDEX(Employees!$K$2:$K$37,MATCH($A43,Employees!$A$2:$A$37,0)) -> IT | D43: =INDEX(Employees!$N$2:$N$37,MATCH($A43,Employees!$A$2:$A$37,0)) -> 5
A44: 7 | B44: =INDEX(Employees!$B$2:$B$37,MATCH($A44,Employees!$A$2:$A$37,0))&" "&INDEX(Employees!$C$2:$C$37,MATCH($A44,Employees!$A$2:$A$37,0)) -> William Jones | C44: =INDEX(Employees!$K$2:$K$37,MATCH($A44,Employees!$A$2:$A$37,0)) -> Customer Support | D44: =INDEX(Employees!$N$2:$N$37,MATCH($A44,Employees!$A$2:$A$37,0)) -> 5

Sheet Supply Chain Analysis
A1: Supply Chain & Inventory Analysis
A2: Stock health, supplier performance and inventory movement
A4: Key Performance Indicators
A5: TOTAL SKUs | C5: SKUs AT/BELOW REORDER LEVEL | E5: TOTAL INVENTORY VALUE | G5: DISCONTINUED W/ STOCK
A6: =COUNTA(Products!A2:A101) -> 100 | C6: =COUNTIF(Products!M2:M101,"REORDER") -> 8 | E6: =SUM(Products!L2:L101) -> 3818708.3 | G6: =COUNTIFS(Products!I2:I101,TRUE(),Products!G2:G101,">0") -> 0
A8: TOTAL RESTOCK UNITS | C8: TOTAL DAMAGED UNITS | E8: AVG SUPPLIER LEAD TIME (days) | G8: AVG SUPPLIER RATING
A9: =SUMIF(InventoryTransactions!D2:D351,"Restock",InventoryTransactions!E2:E351) -> 29554 | C9: =-SUMIF(InventoryTransactions!D2:D351,"Damaged",InventoryTransactions!E2:E351) -> 1317 | E9: =AVERAGE(Suppliers!D2:D13) -> 22.833333 | G9: =AVERAGE(Suppliers!E2:E13) -> 3.8958333
A11: Reorder Alert — Stock At or Below Reorder Level
A12: Product ID | B12: Product Name | C12: Category | D12: Stock Qty | E12: Reorder Level | F12: Supplier
A13: 14 | B13: =INDEX(Products!$B$2:$B$101,MATCH($A13,Products!$A$2:$A$101,0)) -> Sticky Notes | C13: =INDEX(Products!$J$2:$J$101,MATCH($A13,Products!$A$2:$A$101,0)) -> Office Supplies | D13: =INDEX(Products!$G$2:$G$101,MATCH($A13,Products!$A$2:$A$101,0)) -> 13 | E13: =INDEX(Products!$H$2:$H$101,MATCH($A13,Products!$A$2:$A$101,0)) -> 79 | F13: =INDEX(Products!$K$2:$K$101,MATCH($A13,Products!$A$2:$A$101,0)) -> EastPoint Textiles
A14: 3 | B14: =INDEX(Products!$B$2:$B$101,MATCH($A14,Products!$A$2:$A$101,0)) -> USB-C Hub | C14: =INDEX(Products!$J$2:$J$101,MATCH($A14,Products!$A$2:$A$101,0)) -> Electronics | D14: =INDEX(Products!$G$2:$G$101,MATCH($A14,Products!$A$2:$A$101,0)) -> 14 | E14: =INDEX(Products!$H$2:$H$101,MATCH($A14,Products!$A$2:$A$101,0)) -> 44 | F14: =INDEX(Products!$K$2:$K$101,MATCH($A14,Products!$A$2:$A$101,0)) -> Zenith Materials
A15: 39 | B15: =INDEX(Products!$B$2:$B$101,MATCH($A15,Products!$A$2:$A$101,0)) -> Winter Gloves | C15: =INDEX(Products!$J$2:$J$101,MATCH($A15,Products!$A$2:$A$101,0)) -> Apparel | D15: =INDEX(Products!$G$2:$G$101,MATCH($A15,Products!$A$2:$A$101,0)) -> 27 | E15: =INDEX(Products!$H$2:$H$101,MATCH($A15,Products!$A$2:$A$101,0)) -> 29 | F15: =INDEX(Products!$K$2:$K$101,MATCH($A15,Products!$A$2:$A$101,0)) -> Zenith Materials
A16: 68 | B16: =INDEX(Products!$B$2:$B$101,MATCH($A16,Products!$A$2:$A$101,0)) -> Art Supply Kit | C16: =INDEX(Products!$J$2:$J$101,MATCH($A16,Products!$A$2:$A$101,0)) -> Toys & Games | D16: =INDEX(Products!$G$2:$G$101,MATCH($A16,Products!$A$2:$A$101,0)) -> 35 | E16: =INDEX(Products!$H$2:$H$101,MATCH($A16,Products!$A$2:$A$101,0)) -> 37 | F16: =INDEX(Products!$K$2:$K$101,MATCH($A16,Products!$A$2:$A$101,0)) -> Continental Fabrics
A17: 80 | B17: =INDEX(Products!$B$2:$B$101,MATCH($A17,Products!$A$2:$A$101,0)) -> Body Lotion | C17: =INDEX(Products!$J$2:$J$101,MATCH($A17,Products!$A$2:$A$101,0)) -> Health & Beauty | D17: =INDEX(Products!$G$2:$G$101,MATCH($A17,Products!$A$2:$A$101,0)) -> 35 | E17: =INDEX(Products!$H$2:$H$101,MATCH($A17,Products!$A$2:$A$101,0)) -> 35 | F17: =INDEX(Products!$K$2:$K$101,MATCH($A17,Products!$A$2:$A$101,0)) -> Zenith Materials
A18: 43 | B18: =INDEX(Products!$B$2:$B$101,MATCH($A18,Products!$A$2:$A$101,0)) -> Non-stick Pan Set | C18: =INDEX(Products!$J$2:$J$101,MATCH($A18,Products!$A$2:$A$101,0)) -> Home & Kitchen | D18: =INDEX(Products!$G$2:$G$101,MATCH($A18,Products!$A$2:$A$101,0)) -> 50 | E18: =INDEX(Products!$H$2:$H$101,MATCH($A18,Products!$A$2:$A$101,0)) -> 80 | F18: =INDEX(Products!$K$2:$K$101,MATCH($A18,Products!$A$2:$A$101,0)) -> Summit Hardware
A19: 16 | B19: =INDEX(Products!$B$2:$B$101,MATCH($A19,Products!$A$2:$A$101,0)) -> Whiteboard | C19: =INDEX(Products!$J$2:$J$101,MATCH($A19,Products!$A$2:$A$101,0)) -> Office Supplies | D19: =INDEX(Products!$G$2:$G$101,MATCH($A19,Products!$A$2:$A$101,0)) -> 52 | E19: =INDEX(Products!$H$2:$H$101,MATCH($A19,Products!$A$2:$A$101,0)) -> 64 | F19: =INDEX(Products!$K$2:$K$101,MATCH($A19,Products!$A$2:$A$101,0)) -> Summit Hardware
A20: 38 | B20: =INDEX(Products!$B$2:$B$101,MATCH($A20,Products!$A$2:$A$101,0)) -> Leather Belt | C20: =INDEX(Products!$J$2:$J$101,MATCH($A20,Products!$A$2:$A$101,0)) -> Apparel | D20: =INDEX(Products!$G$2:$G$101,MATCH($A20,Products!$A$2:$A$101,0)) -> 58 | E20: =INDEX(Products!$H$2:$H$101,MATCH($A20,Products!$A$2:$A$101,0)) -> 72 | F20: =INDEX(Products!$K$2:$K$101,MATCH($A20,Products!$A$2:$A$101,0)) -> Acme Manufacturing
A22: Supplier Performance Scorecard
A23: Supplier | B23: Country | C23: Lead Time (days) | D23: Rating | E23: Products Supplied | F23: Total Restock Qty
A24: =INDEX(Suppliers!$B$2:$B$13,MATCH(10,Suppliers!$A$2:$A$13,0)) -> Summit Hardware | B24: =INDEX(Suppliers!$C$2:$C$13,MATCH(10,Suppliers!$A$2:$A$13,0)) -> Poland | C24: =INDEX(Suppliers!$D$2:$D$13,MATCH(10,Suppliers!$A$2:$A$13,0)) -> 42 | D24: =INDEX(Suppliers!$E$2:$E$13,MATCH(10,Suppliers!$A$2:$A$13,0)) -> 4.88 | E24: =INDEX(Suppliers!$F$2:$F$13,MATCH(10,Suppliers!$A$2:$A$13,0)) -> 8 | F24: =INDEX(Suppliers!$G$2:$G$13,MATCH(10,Suppliers!$A$2:$A$13,0)) -> 3021
A25: =INDEX(Suppliers!$B$2:$B$13,MATCH(2,Suppliers!$A$2:$A$13,0)) -> Global Parts Ltd | B25: =INDEX(Suppliers!$C$2:$C$13,MATCH(2,Suppliers!$A$2:$A$13,0)) -> USA | C25: =INDEX(Suppliers!$D$2:$D$13,MATCH(2,Suppliers!$A$2:$A$13,0)) -> 25 | D25: =INDEX(Suppliers!$E$2:$E$13,MATCH(2,Suppliers!$A$2:$A$13,0)) -> 4.76 | E25: =INDEX(Suppliers!$F$2:$F$13,MATCH(2,Suppliers!$A$2:$A$13,0)) -> 11 | F25: =INDEX(Suppliers!$G$2:$G$13,MATCH(2,Suppliers!$A$2:$A$13,0)) -> 3607
A26: =INDEX(Suppliers!$B$2:$B$13,MATCH(11,Suppliers!$A$2:$A$13,0)) -> Redwood Electronics | B26: =INDEX(Suppliers!$C$2:$C$13,MATCH(11,Suppliers!$A$2:$A$13,0)) -> Taiwan | C26: =INDEX(Suppliers!$D$2:$D$13,MATCH(11,Suppliers!$A$2:$A$13,0)) -> 6 | D26: =INDEX(Suppliers!$E$2:$E$13,MATCH(11,Suppliers!$A$2:$A$13,0)) -> 4.68 | E26: =INDEX(Suppliers!$F$2:$F$13,MATCH(11,Suppliers!$A$2:$A$13,0)) -> 8 | F26: =INDEX(Suppliers!$G$2:$G$13,MATCH(11,Suppliers!$A$2:$A$13,0)) -> 2411
A27: =INDEX(Suppliers!$B$2:$B$13,MATCH(5,Suppliers!$A$2:$A$13,0)) -> Pacific Rim Supply | B27: =INDEX(Suppliers!$C$2:$C$13,MATCH(5,Suppliers!$A$2:$A$13,0)) -> India | C27: =INDEX(Suppliers!$D$2:$D$13,MATCH(5,Suppliers!$A$2:$A$13,0)) -> 14 | D27: =INDEX(Suppliers!$E$2:$E$13,MATCH(5,Suppliers!$A$2:$A$13,0)) -> 4.35 | E27: =INDEX(Suppliers!$F$2:$F$13,MATCH(5,Suppliers!$A$2:$A$13,0)) -> 12 | F27: =INDEX(Suppliers!$G$2:$G$13,MATCH(5,Suppliers!$A$2:$A$13,0)) -> 3359
A28: =INDEX(Suppliers!$B$2:$B$13,MATCH(7,Suppliers!$A$2:$A$13,0)) -> BrightPath Goods | B28: =INDEX(Suppliers!$C$2:$C$13,MATCH(7,Suppliers!$A$2:$A$13,0)) -> South Korea | C28: =INDEX(Suppliers!$D$2:$D$13,MATCH(7,Suppliers!$A$2:$A$13,0)) -> 26 | D28: =INDEX(Suppliers!$E$2:$E$13,MATCH(7,Suppliers!$A$2:$A$13,0)) -> 3.99 | E28: =INDEX(Suppliers!$F$2:$F$13,MATCH(7,Suppliers!$A$2:$A$13,0)) -> 12 | F28: =INDEX(Suppliers!$G$2:$G$13,MATCH(7,Suppliers!$A$2:$A$13,0)) -> 3282
A29: =INDEX(Suppliers!$B$2:$B$13,MATCH(6,Suppliers!$A$2:$A$13,0)) -> Ironwood Industries | B29: =INDEX(Suppliers!$C$2:$C$13,MATCH(6,Suppliers!$A$2:$A$13,0)) -> Mexico | C29: =INDEX(Suppliers!$D$2:$D$13,MATCH(6,Suppliers!$A$2:$A$13,0)) -> 9 | D29: =INDEX(Suppliers!$E$2:$E$13,MATCH(6,Suppliers!$A$2:$A$13,0)) -> 3.71 | E29: =INDEX(Suppliers!$F$2:$F$13,MATCH(6,Suppliers!$A$2:$A$13,0)) -> 3 | F29: =INDEX(Suppliers!$G$2:$G$13,MATCH(6,Suppliers!$A$2:$A$13,0)) -> 872
A30: =INDEX(Suppliers!$B$2:$B$13,MATCH(9,Suppliers!$A$2:$A$13,0)) -> Continental Fabrics | B30: =INDEX(Suppliers!$C$2:$C$13,MATCH(9,Suppliers!$A$2:$A$13,0)) -> Turkey | C30: =INDEX(Suppliers!$D$2:$D$13,MATCH(9,Suppliers!$A$2:$A$13,0)) -> 31 | D30: =INDEX(Suppliers!$E$2:$E$13,MATCH(9,Suppliers!$A$2:$A$13,0)) -> 3.66 | E30: =INDEX(Suppliers!$F$2:$F$13,MATCH(9,Suppliers!$A$2:$A$13,0)) -> 4 | F30: =INDEX(Suppliers!$G$2:$G$13,MATCH(9,Suppliers!$A$2:$A$13,0)) -> 805
A31: =INDEX(Suppliers!$B$2:$B$13,MATCH(4,Suppliers!$A$2:$A$13,0)) -> Nordic Components | B31: =INDEX(Suppliers!$C$2:$C$13,MATCH(4,Suppliers!$A$2:$A$13,0)) -> Vietnam | C31: =INDEX(Suppliers!$D$2:$D$13,MATCH(4,Suppliers!$A$2:$A$13,0)) -> 19 | D31: =INDEX(Suppliers!$E$2:$E$13,MATCH(4,Suppliers!$A$2:$A$13,0)) -> 3.64 | E31: =INDEX(Suppliers!$F$2:$F$13,MATCH(4,Suppliers!$A$2:$A$13,0)) -> 7 | F31: =INDEX(Suppliers!$G$2:$G$13,MATCH(4,Suppliers!$A$2:$A$13,0)) -> 3645
A32: =INDEX(Suppliers!$B$2:$B$13,MATCH(12,Suppliers!$A$2:$A$13,0)) -> Falcon Packaging | B32: =INDEX(Suppliers!$C$2:$C$13,MATCH(12,Suppliers!$A$2:$A$13,0)) -> Canada | C32: =INDEX(Suppliers!$D$2:$D$13,MATCH(12,Suppliers!$A$2:$A$13,0)) -> 41 | D32: =INDEX(Suppliers!$E$2:$E$13,MATCH(12,Suppliers!$A$2:$A$13,0)) -> 3.64 | E32: =INDEX(Suppliers!$F$2:$F$13,MATCH(12,Suppliers!$A$2:$A$13,0)) -> 11 | F32: =INDEX(Suppliers!$G$2:$G$13,MATCH(12,Suppliers!$A$2:$A$13,0)) -> 2662
A33: =INDEX(Suppliers!$B$2:$B$13,MATCH(1,Suppliers!$A$2:$A$13,0)) -> Acme Manufacturing | B33: =INDEX(Suppliers!$C$2:$C$13,MATCH(1,Suppliers!$A$2:$A$13,0)) -> China | C33: =INDEX(Suppliers!$D$2:$D$13,MATCH(1,Suppliers!$A$2:$A$13,0)) -> 20 | D33: =INDEX(Suppliers!$E$2:$E$13,MATCH(1,Suppliers!$A$2:$A$13,0)) -> 3.4 | E33: =INDEX(Suppliers!$F$2:$F$13,MATCH(1,Suppliers!$A$2:$A$13,0)) -> 9 | F33: =INDEX(Suppliers!$G$2:$G$13,MATCH(1,Suppliers!$A$2:$A$13,0)) -> 2613
A34: =INDEX(Suppliers!$B$2:$B$13,MATCH(3,Suppliers!$A$2:$A$13,0)) -> EastPoint Textiles | B34: =INDEX(Suppliers!$C$2:$C$13,MATCH(3,Suppliers!$A$2:$A$13,0)) -> Germany | C34: =INDEX(Suppliers!$D$2:$D$13,MATCH(3,Suppliers!$A$2:$A$13,0)) -> 10 | D34: =INDEX(Suppliers!$E$2:$E$13,MATCH(3,Suppliers!$A$2:$A$13,0)) -> 3.1 | E34: =INDEX(Suppliers!$F$2:$F$13,MATCH(3,Suppliers!$A$2:$A$13,0)) -> 3 | F34: =INDEX(Suppliers!$G$2:$G$13,MATCH(3,Suppliers!$A$2:$A$13,0)) -> 334
A35: =INDEX(Suppliers!$B$2:$B$13,MATCH(8,Suppliers!$A$2:$A$13,0)) -> Zenith Materials | B35: =INDEX(Suppliers!$C$2:$C$13,MATCH(8,Suppliers!$A$2:$A$13,0)) -> Italy | C35: =INDEX(Suppliers!$D$2:$D$13,MATCH(8,Suppliers!$A$2:$A$13,0)) -> 31 | D35: =INDEX(Suppliers!$E$2:$E$13,MATCH(8,Suppliers!$A$2:$A$13,0)) -> 2.94 | E35: =INDEX(Suppliers!$F$2:$F$13,MATCH(8,Suppliers!$A$2:$A$13,0)) -> 12 | F35: =INDEX(Suppliers!$G$2:$G$13,MATCH(8,Suppliers!$A$2:$A$13,0)) -> 2943
A37: Inventory Movement by Transaction Type
A38: Transaction Type | B38: Transaction Count | C38: Total Units
A39: Restock | B39: =COUNTIF(InventoryTransactions!$D$2:$D$351,$A39) -> 169 | C39: =SUMIF(InventoryTransactions!$D$2:$D$351,$A39,InventoryTransactions!$E$2:$E$351) -> 29554
A40: Sale | B40: =COUNTIF(InventoryTransactions!$D$2:$D$351,$A40) -> 51 | C40: =SUMIF(InventoryTransactions!$D$2:$D$351,$A40,InventoryTransactions!$E$2:$E$351) -> -1161
A41: Return | B41: =COUNTIF(InventoryTransactions!$D$2:$D$351,$A41) -> 0 | C41: =SUMIF(InventoryTransactions!$D$2:$D$351,$A41,InventoryTransactions!$E$2:$E$351) -> 0
A42: Adjustment | B42: =COUNTIF(InventoryTransactions!$D$2:$D$351,$A42) -> 68 | C42: =SUMIF(InventoryTransactions!$D$2:$D$351,$A42,InventoryTransactions!$E$2:$E$351) -> -1554
A43: Damaged | B43: =COUNTIF(InventoryTransactions!$D$2:$D$351,$A43) -> 62 | C43: =SUMIF(InventoryTransactions!$D$2:$D$351,$A43,InventoryTransactions!$E$2:$E$351) -> -1317
A45: Inventory Value & Sell-Through by Category
A46: Category | B46: Inventory Value | C46: Units Sold (YTD all) | D46: Sell-Through Ratio
...

Sheet Departments
A1: Retail & Distribution Co. Executive Dashboard | B1: department name | C1: budget | D1: Headcount | E1: Total Salary Cost | F1: Budget Variance | G1: Budget Utilization %
A2: Sales · Finance · HR · Supply Chain | B2: Sales | C2: 500000 | D2: =COUNTIF(Employees!$E$2:$E$37,A2) -> 0 | E2: =SUMIF(Employees!$E$2:$E$37,A2,Employees!$I$2:$I$37) -> 0 | F2: =C2-E2 -> 500000 | G2: =IFERROR(E2/C2,0) -> 0
A3: 2 | B3: Marketing | C3: 250000 | D3: =COUNTIF(Employees!$E$2:$E$37,A3) -> 4 | E3: =SUMIF(Employees!$E$2:$E$37,A3,Employees!$I$2:$I$37) -> 355891.84 | F3: =C3-E3 -> -105891.84 | G3: =IFERROR(E3/C3,0) -> 1.4235674
A4: 3 | B4: Finance | C4: 300000 | D4: =COUNTIF(Employees!$E$2:$E$37,A4) -> 6 | E4: =SUMIF(Employees!$E$2:$E$37,A4,Employees!$I$2:$I$37) -> 458531.52 | F4: =C4-E4 -> -158531.52 | G4: =IFERROR(E4/C4,0) -> 1.5284384
A5: 4 | B5: Operations | C5: 450000 | D5: =COUNTIF(Employees!$E$2:$E$37,A5) -> 4 | E5: =SUMIF(Employees!$E$2:$E$37,A5,Employees!$I$2:$I$37) -> 338462.72 | F5: =C5-E5 -> 111537.28 | G5: =IFERROR(E5/C5,0) -> 0.75213938
A6: 5 | B6: Human Resources | C6: 150000 | D6: =COUNTIF(Employees!$E$2:$E$37,A6) -> 6 | E6: =SUMIF(Employees!$E$2:$E$37,A6,Employees!$I$2:$I$37) -> 477814.43 | F6: =C6-E6 -> -327814.43 | G6: =IFERROR(E6/C6,0) -> 3.1854295
A7: 6 | B7: IT | C7: 350000 | D7: =COUNTIF(Employees!$E$2:$E$37,A7) -> 6 | E7: =SUMIF(Employees!$E$2:$E$37,A7,Employees!$I$2:$I$37) -> 431307.33 | F7: =C7-E7 -> -81307.33 | G7: =IFERROR(E7/C7,0) -> 1.2323067
A8: 7 | B8: Customer Support | C8: 200000 | D8: =COUNTIF(Employees!$E$2:$E$37,A8) -> 6 | E8: =SUMIF(Employees!$E$2:$E$37,A8,Employees!$I$2:$I$37) -> 508330.64 | F8: =C8-E8 -> -308330.64 | G8: =IFERROR(E8/C8,0) -> 2.5416532
A12: Chart Data

Sheet Employees
A1: employee id | B1: first name | C1: last name | D1: email | E1: department id | F1: manager id | G1: job title | H1: hire date | I1: salary | J1: region | K1: Department Name | L1: Tenure (Years) | M1: Manager Name | N1: Direct Reports | O1: Orders Handled | P1: Revenue Generated
A2: 1 | B2: Daniel | C2: Brown | D2: daniel.brown1@company.com | E2: 1 | G2: Account Executive | H2: 2015-02-21 | I2: 118369.77 | J2: Europe | K2: =IFERROR(INDEX(Departments!$B$2:$B$8,MATCH(E2,Departments!$A$2:$A$8,0)),"Unassigned") -> Unassigned | L2: =ROUND((TODAY()-H2)/365.25,1) -> 11.5 | M2: =IFERROR(INDEX($B$2:$B$37,MATCH(F2,$A$2:$A$37,0))&" "&INDEX($C$2:$C$37,MATCH(F2,$A$2:$A$37,0)),"(Top Level)") -> (Top Level) | N2: =COUNTIF($F$2:$F$37,A2) -> 3 | O2: =COUNTIF(Orders!$C$2:$C$401,A2) -> 89 | P2: =SUMIF(Orders!$C$2:$C$401,A2,Orders!$H$2:$H$401) -> 377581.84
A3: 2 | B3: Linda | C3: Jones | D3: linda.jones2@company.com | E3: 2 | G3: SEO Analyst | H3: 2015-07-29 | I3: 115451.48 | J3: Middle East | K3: =IFERROR(INDEX(Departments!$B$2:$B$8,MATCH(E3,Departments!$A$2:$A$8,0)),"Unassigned") -> Marketing | L3: =ROUND((TODAY()-H3)/365.25,1) -> 11.1 | M3: =IFERROR(INDEX($B$2:$B$37,MATCH(F3,$A$2:$A$37,0))&" "&INDEX($C$2:$C$37,MATCH(F3,$A$2:$A$37,0)),"(Top Level)") -> (Top Level) | N3: =COUNTIF($F$2:$F$37,A3) -> 3 | O3: =COUNTIF(Orders!$C$2:$C$401,A3) -> 0 | P3: =SUMIF(Orders!$C$2:$C$401,A3,Orders!$H$2:$H$401) -> 0
A4: 3 | B4: John | C4: Jackson | D4: john.jackson3@company.com | E4: 3 | G4: Controller | H4: 2017-05-14 | I4: 86430.22 | J4: North America | K4: =IFERROR(INDEX(Departments!$B$2:$B$8,MATCH(E4,Departments!$A$2:$A$8,0)),"Unassigned") -> Finance | L4: =ROUND((TODAY()-H4)/365.25,1) -> 9.3 | M4: =IFERROR(INDEX($B$2:$B$37,MATCH(F4,$A$2:$A$37,0))&" "&INDEX($C$2:$C$37,MATCH(F4,$A$2:$A$37,0)),"(Top Level)") -> (Top Level) | N4: =COUNTIF($F$2:$F$37,A4) -> 5 | O4: =COUNTIF(Orders!$C$2:$C$401,A4) -> 0 | P4: =SUMIF(Orders!$C$2:$C$401,A4,Orders!$H$2:$H$401) -> 0
A5: 4 | B5: Michael | C5: Davis | D5: michael.davis4@company.com | E5: 4 | G5: Warehouse Supervisor | H5: 2017-10-31 | I5: 112090.84 | J5: Middle East | K5: =IFERROR(INDEX(Departments!$B$2:$B$8,MATCH(E5,Departments!$A$2:$A$8,0)),"Unassigned") -> Operations | L5: =ROUND((TODAY()-H5)/365.25,1) -> 8.9 | M5: =IFERROR(INDEX($B$2:$B$37,MATCH(F5,$A$2:$A$37,0))&" "&INDEX($C$2:$C$37,MATCH(F5,$A$2:$A$37,0)),"(Top Level)") -> (Top Level) | N5: =COUNTIF($F$2:$F$37,A5) -> 3 | O5: =COUNTIF(Orders!$C$2:$C$401,A5) -> 0 | P5: =SUMIF(Orders!$C$2:$C$401,A5,Orders!$H$2:$H$401) -> 0
A6: 5 | B6: Michael | C6: Moore | D6: michael.moore5@company.com | E6: 5 | G6: HR Manager | H6: 2017-05-09 | I6: 94919.83 | J6: Middle East | K6: =IFERROR(INDEX(Departments!$B$2:$B$8,MATCH(E6,Departments!$A$2:$A$8,0)),"Unassigned") -> Human Resources | L6: =ROUND((TODAY()-H6)/365.25,1) -> 9.3 | M6: =IFERROR(INDEX($B$2:$B$37,MATCH(F6,$A$2:$A$37,0))&" "&INDEX($C$2:$C$37,MATCH(F6,$A$2:$A$37,0)),"(Top Level)") -> (Top Level) | N6: =COUNTIF($F$2:$F$37,A6) -> 5 | O6: =COUNTIF(Orders!$C$2:$C$401,A6) -> 0 | P6: =SUMIF(Orders!$C$2:$C$401,A6,Orders!$H$2:$H$401) -> 0
A7: 6 | B7: William | C7: Smith | D7: william.smith6@company.com | E7: 6 | G7: IT Manager | H7: 2015-11-23 | I7: 116416.27 | J7: Asia Pacific | K7: =IFERROR(INDEX(Departments!$B$2:$B$8,MATCH(E7,Departments!$A$2:$A$8,0)),"Unassigned") -> IT | L7: =ROUND((TODAY()-H7)/365.25,1) -> 10.8 | M7: =IFERROR(INDEX($B$2:$B$37,MATCH(F7,$A$2:$A$37,0))&" "&INDEX($C$2:$C$37,MATCH(F7,$A$2:$A$37,0)),"(Top Level)") -> (Top Level) | N7: =COUNTIF($F$2:$F$37,A7) -> 5 | O7: =COUNTIF(Orders!$C$2:$C$401,A7) -> 0 | P7: =SUMIF(Orders!$C$2:$C$401,A7,Orders!$H$2:$H$401) -> 0
A8: 7 | B8: William | C8: Jones | D8: william.jones7@company.com | E8: 7 | G8: Customer Success Manager | H8: 2016-03-16 | I8: 128074.59 | J8: Asia Pacific | K8: =IFERROR(INDEX(Departments!$B$2:$B$8,MATCH(E8,Departments!$A$2:$A$8,0)),"Unassigned") -> Customer Support | L8: =ROUND((TODAY()-H8)/365.25,1) -> 10.5 | M8: =IFERROR(INDEX($B$2:$B$37,MATCH(F8,$A$2:$A$37,0))&" "&INDEX($C$2:$C$37,MATCH(F8,$A$2:$A$37,0)),"(Top Level)") -> (Top Level) | N8: =COUNTIF($F$2:$F$37,A8) -> 5 | O8: =COUNTIF(Orders!$C$2:$C$401,A8) -> 0 | P8: =SUMIF(Orders!$C$2:$C$401,A8,Orders!$H$2:$H$401) -> 0
A9: 8 | B9: John | C9: Gonzalez | D9: john.gonzalez8@company.com | E9: 1 | F9: 1 | G9: Senior Sales Rep | H9: 2017-01-31 | I9: 87374.72 | J9: Middle East | K9: =IFERROR(INDEX(Departments!$B$2:$B$8,MATCH(E9,Departments!$A$2:$A$8,0)),"Unassigned") -> Unassigned | L9: =ROUND((TODAY()-H9)/365.25,1) -> 9.6 | M9: =IFERROR(INDEX($B$2:$B$37,MATCH(F9,$A$2:$A$37,0))&" "&INDEX($C$2:$C$37,MATCH(F9,$A$2:$A$37,0)),"(Top Level)") -> Daniel Brown | N9: =COUNTIF($F$2:$F$37,A9) -> 0 | O9: =COUNTIF(Orders!$C$2:$C$401,A9) -> 115 | P9: =SUMIF(Orders!$C$2:$C$401,A9,Orders!$H$2:$H$401) -> 497216.81
A10: 9 | B10: William | C10: Johnson | D10: william.johnson9@company.com | E10: 1 | F10: 1 | G10: Sales Manager | H10: 2024-03-07 | I10: 71811.4 | J10: Latin America | K10: =IFERROR(INDEX(Departments!$B$2:$B$8,MATCH(E10,Departments!$A$2:$A$8,0)),"Unassigned") -> Unassigned | L10: =ROUND((TODAY()-H10)/365.25,1) -> 2.5 | M10: =IFERROR(INDEX($B$2:$B$37,MATCH(F10,$A$2:$A$37,0))&" "&INDEX($C$2:$C$37,MATCH(F10,$A$2:$A$37,0)),"(Top Level)") -> Daniel Brown | N10: =COUNTIF($F$2:$F$37,A10) -> 0 | O10: =COUNTIF(Orders!$C$2:$C$401,A10) -> 93 | P10: =SUMIF(Orders!$C$2:$C$401,A10,Orders!$H$2:$H$401) -> 419101.89
A11: 10 | B11: John | C11: Moore | D11: john.moore10@company.com | E11: 1 | F11: 1 | G11: Senior Sales Rep | H11: 2019-04-15 | I11: 73867.61 | J11: North America | K11: =IFERROR(INDEX(Departments!$B$2:$B$8,MATCH(E11,Departments!$A$2:$A$8,0)),"Unassigned") -> Unassigned | L11: =ROUND((TODAY()-H11)/365.25,1) -> 7.4 | M11: =IFERROR(INDEX($B$2:$B$37,MATCH(F11,$A$2:$A$37,0))&" "&INDEX($C$2:$C$37,MATCH(F11,$A$2:$A$37,0)),"(Top Level)") -> Daniel Brown | N11: =COUNTIF($F$2:$F$37,A11) -> 0 | O11: =COUNTIF(Orders!$C$2:$C$401,A11) -> 103 | P11: =SUMIF(Orders!$C$2:$C$401,A11,Orders!$H$2:$H$401) -> 461776.55
A12: 11 | B12: Nancy | C12: Davis | D12: nancy.davis11@company.com | E12: 2 | F12: 2 | G12: Content Strategist | H12: 2024-09-01 | I12: 94261.08 | J12: Europe | K12: =IFERROR(INDEX(Departments!$B$2:$B$8,MATCH(E12,Departments!$A$2:$A$8,0)),"Unassigned") -> Marketing | L12: =ROUND((TODAY()-H12)/365.25,1) -> 2 | M12: =IFERROR(INDEX($B$2:$B$37,MATCH(F12,$A$2:$A$37,0))&" "&INDEX($C$2:$C$37,MATCH(F12,$A$2:$A$37,0)),"(Top Level)") -> Linda Jones | N12: =COUNTIF($F$2:$F$37,A12) -> 0 | O12: =COUNTIF(Orders!$C$2:$C$401,A12) -> 0 | P12: =SUMIF(Orders!$C$2:$C$401,A12,Orders!$H$2:$H$401) -> 0
A13: 12 | B13: Margaret | C13: Brown | D13: margaret.brown12@company.com | E13: 2 | F13: 2 | G13: Content Strategist | H13: 2020-04-05 | I13: 67670.52 | J13: Asia Pacific | K13: =IFERROR(INDEX(Departments!$B$2:$B$8,MATCH(E13,Departments!$A$2:$A$8,0)),"Unassigned") -> Marketing | L13: =ROUND((TODAY()-H13)/365.25,1) -> 6.4 | M13: =IFERROR(INDEX($B$2:$B$37,MATCH(F13,$A$2:$A$37,0))&" "&INDEX($C$2:$C$37,MATCH(F13,$A$2:$A$37,0)),"(Top Level)") -> Linda Jones | N13: =COUNTIF($F$2:$F$37,A13) -> 0 | O13: =COUNTIF(Orders!$C$2:$C$401,A13) -> 0 | P13: =SUMIF(Orders!$C$2:$C$401,A13,Orders!$H$2:$H$401) -> 0
A14: 13 | B14: Jennifer | C14: Lopez | D14: jennifer.lopez13@company.com | E14: 2 | F14: 2 | G14: Marketing Specialist | H14: 2019-12-26 | I14: 78508.76 | J14: North America | K14: =IFERROR(INDEX(Departments!$B$2:$B$8,MATCH(E14,Departments!$A$2:$A$8,0)),"Unassigned") -> Marketing | L14: =ROUND((TODAY()-H14)/365.25,1) -> 6.7 | M14: =IFERROR(INDEX($B$2:$B$37,MATCH(F14,$A$2:$A$37,0))&" "&INDEX($C$2:$C$37,MATCH(F14,$A$2:$A$37,0)),"(Top Level)") -> Linda Jones | N14: =COUNTIF($F$2:$F$37,A14) -> 0 | O14: =COUNTIF(Orders!$C$2:$C$401,A14) -> 0 | P14: =SUMIF(Orders!$C$2:$C$401,A14,Orders!$H$2:$H$401) -> 0
A15: 14 | B15: Daniel | C15: Garcia | D15: daniel.garcia14@company.com | E15: 3 | F15: 3 | G15: Finance Manager | H15: 2021-12-27 | I15: 57240.55 | J15: Latin America | K15: =IFERROR(INDEX(Departments!$B$2:$B$8,MATCH(E15,Departments!$A$2:$A$8,0)),"Unassigned") -> Finance | L15: =ROUND((TODAY()-H15)/365.25,1) -> 4.7 | M15: =IFERROR(INDEX($B$2:$B$37,MATCH(F15,$A$2:$A$37,0))&" "&INDEX($C$2:$C$37,MATCH(F15,$A$2:$A$37,0)),"(Top Level)") -> John Jackson | N15: =COUNTIF($F$2:$F$37,A15) -> 0 | O15: =COUNTIF(Orders!$C$2:$C$401,A15) -> 0 | P15: =SUMIF(Orders!$C$2:$C$401,A15,Orders!$H$2:$H$401) -> 0
A16: 15 | B16: Richard | C16: Rodriguez | D16: richard.rodriguez15@company.com | E16: 3 | F16: 3 | G16: Finance Manager | H16: 2023-03-06 | I16: 72847.49 | J16: Asia Pacific | K16: =IFERROR(INDEX(Departments!$B$2:$B$8,MATCH(E16,Departments!$A$2:$A$8,0)),"Unassigned") -> Finance | L16: =ROUND((TODAY()-H16)/365.25,1) -> 3.5 | M16: =IFERROR(INDEX($B$2:$B$37,MATCH(F16,$A$2:$A$37,0))&" "&INDEX($C$2:$C$37,MATCH(F16,$A$2:$A$37,0)),"(Top Level)") -> John Jackson | N16: =COUNTIF($F$2:$F$37,A16) -> 0 | O16: =COUNTIF(Orders!$C$2:$C$401,A16) -> 0 | P16: =SUMIF(Orders!$C$2:$C$401,A16,Orders!$H$2:$H$401) -> 0
A17: 16 | B17: Mark | C17: Johnson | D17: mark.johnson16@company.com | E17: 3 | F17: 3 | G17: Financial Analyst | H17: 2018-07-27 | I17: 85252.29 | J17: Latin America | K17: =IFERROR(INDEX(Departments!$B$2:$B$8,MATCH(E17,Departments!$A$2:$A$8,0)),"Unassigned") -> Finance | L17: =ROUND((TODAY()-H17)/365.25,1) -> 8.1 | M17: =IFERROR(INDEX($B$2:$B$37,MATCH(F17,$A$2:$A$37,0))&" "&INDEX($C$2:$C$37,MATCH(F17,$A$2:$A$37,0)),"(Top Level)") -> John Jackson | N17: =COUNTIF($F$2:$F$37,A17) -> 0 | O17: =COUNTIF(Orders!$C$2:$C$401,A17) -> 0 | P17: =SUMIF(Orders!$C$2:$C$401,A17,Orders!$H$2:$H$401) -> 0
A18: 17 | B18: William | C18: Williams | D18: william.williams17@company.com | E18: 3 | F18: 3 | G18: Finance Manager | H18: 2018-05-14 | I18: 88818.38 | J18: Asia Pacific | K18: =IFERROR(INDEX(Departments!$B$2:$B$8,MATCH(E18,Departments!$A$2:$A$8,0)),"Unassigned") -> Finance | L18: =ROUND((TODAY()-H18)/365.25,1) -> 8.3 | M18: =IFERROR(INDEX($B$2:$B$37,MATCH(F18,$A$2:$A$37,0))&" "&INDEX($C$2:$C$37,MATCH(F18,$A$2:$A$37,0)),"(Top Level)") -> John Jackson | N18: =COUNTIF($F$2:$F$37,A18) -> 0 | O18: =COUNTIF(Orders!$C$2:$C$401,A18) -> 0 | P18: =SUMIF(Orders!$C$2:$C$401,A18,Orders!$H$2:$H$401) -> 0
A19: 18 | B19: Michael | C19: Thomas | D19: michael.thomas18@company.com | E19: 3 | F19: 3 | G19: Finance Manager | H19: 2020-06-08 | I19: 67942.59 | J19: Asia Pacific | K19: =IFERROR(INDEX(Departments!$B$2:$B$8,MATCH(E19,Departments!$A$2:$A$8,0)),"Unassigned") -> Finance | L19: =ROUND((TODAY()-H19)/365.25,1) -> 6.3 | M19: =IFERROR(INDEX($B$2:$B$37,MATCH(F19,$A$2:$A$37,0))&" "&INDEX($C$2:$C$37,MATCH(F19,$A$2:$A$37,0)),"(Top Level)") -> John Jackson | N19: =COUNTIF($F$2:$F$37,A19) -> 0 | O19: =COUNTIF(Orders!$C$2:$C$401,A19) -> 0 | P19: =SUMIF(Orders!$C$2:$C$401,A19,Orders!$H$2:$H$401) -> 0
A20: 19 | B20: Linda | C20: Moore | D20: linda.moore19@company.com | E20: 4 | F20: 4 | G20: Logistics Coordinator | H20: 2022-01-16 | I20: 82350.69 | J20: Latin America | K20: =IFERROR(INDEX(Departments!$B$2:$B$8,MATCH(E20,Departments!$A$2:$A$8,0)),"Unassigned") -> Operations | L20: =ROUND((TODAY()-H20)/365.25,1) -> 4.6 | M20: =IFERROR(INDEX($B$2:$B$37,MATCH(F20,$A$2:$A$37,0))&" "&INDEX($C$2:$C$37,MATCH(F20,$A$2:$A$37,0)),"(Top Level)") -> Michael Davis | N20: =COUNTIF($F$2:$F$37,A20) -> 0 | O20: =COUNTIF(Orders!$C$2:$C$401,A20) -> 0 | P20: =SUMIF(Orders!$C$2:$C$401,A20,Orders!$H$2:$H$401) -> 0
... A37: 36 | B37: John | C37: Johnson | D37: john.johnson36@company.com | E37: 7 | F37: 7 | G37: Support Agent | H37: 2018-07-26 | I37: 90271 | J37: Asia Pacific | K37: =IFERROR(INDEX(Departments!$B$2:$B$8,MATCH(E37,Departments!$A$2:$A$8,0)),"Unassigned") -> Customer Support | L37: =ROUND((TODAY()-H37)/365.25,1) -> 8.1 | M37: =IFERROR(INDEX($B$2:$B$37,MATCH(F37,$A$2:$A$37,0))&" "&INDEX($C$2:$C$37,MATCH(F37,$A$2:$A$37,0)),"(Top Level)") -> William Jones | N37: =COUNTIF($F$2:$F$37,A37) -> 0 | O37: =COUNTIF(Orders!$C$2:$C$401,A37) -> 0 | P37: =SUMIF(Orders!$C$2:$C$401,A37,Orders!$H$2:$H$401) -> 0

Sheet Customers
A1: customer_id | B1: company name | C1: contact name | D1: email | E1: country | F1: city | G1: segment | H1: signup date | I1: Total Orders | J1: Total Revenue | K1: Avg Order Value
A2: 1 | B2: Summit Industries | C2: Linda Rodriguez | D2: linda.rodriguez1@example.com | E2: Italy | F2: Milan | G2: Corporate | H2: 2021-05-27 | I2: =COUNTIF(Orders!$B$2:$B$401,A2) -> 5 | J2: =SUMIF(Orders!$B$2:$B$401,A2,Orders!$H$2:$H$401) -> 30053.016 | K2: =IFERROR(J2/I2,0) -> 6010.6032
A3: 2 | B3: Ironclad Logistics | C3: Lisa Jackson | D3: lisa.jackson2@example.com | E3: UAE | F3: Dubai | G3: Corporate | H3: 2021-09-22 | I3: =COUNTIF(Orders!$B$2:$B$401,A3) -> 3 | J3: =SUMIF(Orders!$B$2:$B$401,A3,Orders!$H$2:$H$401) -> 15188.331 | K3: =IFERROR(J3/I3,0) -> 5062.777
A4: 3 | B4: Crestline Wholesale | C4: Susan Miller | D4: susan.miller3@example.com | E4: USA | F4: Seattle | G4: Consumer | H4: 2023-11-01 | I4: =COUNTIF(Orders!$B$2:$B$401,A4) -> 3 | J4: =SUMIF(Orders!$B$2:$B$401,A4,Orders!$H$2:$H$401) -> 18853.145 | K4: =IFERROR(J4/I4,0) -> 6284.3818
A5: 4 | B5: Silver Group | C5: Susan Anderson | D5: susan.anderson4@example.com | E5: USA | F5: Chicago | G5: Small Business | H5: 2020-02-08 | I5: =COUNTIF(Orders!$B$2:$B$401,A5) -> 4 | J5: =SUMIF(Orders!$B$2:$B$401,A5,Orders!$H$2:$H$401) -> 10838.086 | K5: =IFERROR(J5/I5,0) -> 2709.5216
A6: 5 | B6: Prime Group | C6: Lisa Hernandez | D6: lisa.hernandez5@example.com | E6: USA | F6: Seattle | G6: Consumer | H6: 2021-02-23 | I6: =COUNTIF(Orders!$B$2:$B$401,A6) -> 4 | J6: =SUMIF(Orders!$B$2:$B$401,A6,Orders!$H$2:$H$401) -> 21579.464 | K6: =IFERROR(J6/I6,0) -> 5394.866
A7: 6 | B7: Nova Industries | C7: Joseph Jones | D7: joseph.jones6@example.com | E7: Australia | F7: Melbourne | G7: Consumer | H7: 2022-02-14 | I7: =COUNTIF(Orders!$B$2:$B$401,A7) -> 10 | J7: =SUMIF(Orders!$B$2:$B$401,A7,Orders!$H$2:$H$401) -> 46488.101 | K7: =IFERROR(J7/I7,0) -> 4648.8101
A8: 7 | B8: Urban Supply Co | C8: Margaret Williams | D8: margaret.williams7@example.com | E8: Japan | F8: Tokyo | G8: Small Business | H8: 2020-02-06 | I8: =COUNTIF(Orders!$B$2:$B$401,A8) -> 4 | J8: =SUMIF(Orders!$B$2:$B$401,A8,Orders!$H$2:$H$401) -> 17833.693 | K8: =IFERROR(J8/I8,0) -> 4458.4233
A9: 8 | B9: Prime Solutions | C9: Sarah Smith | D9: sarah.smith8@example.com | E9: USA | F9: Austin | G9: Consumer | H9: 2020-11-12 | I9: =COUNTIF(Orders!$B$2:$B$401,A9) -> 9 | J9: =SUMIF(Orders!$B$2:$B$401,A9,Orders!$H$2:$H$401) -> 28811.665 | K9: =IFERROR(J9/I9,0) -> 3201.2962
A10: 9 | B10: Northern Distributors | C10: Jessica Miller | D10: jessica.miller9@example.com | E10: Australia | F10: Sydney | G10: Consumer | H10: 2020-11-05 | I10: =COUNTIF(Orders!$B$2:$B$401,A10) -> 4 | J10: =SUMIF(Orders!$B$2:$B$401,A10,Orders!$H$2:$H$401) -> 14596.396 | K10: =IFERROR(J10/I10,0) -> 3649.099
A11: 10 | B11: Horizon Traders | C11: Richard Rodriguez | D11: richard.rodriguez10@example.com | E11: Japan | F11: Tokyo | G11: Corporate | H11: 2023-09-29 | I11: =COUNTIF(Orders!$B$2:$B$401,A11) -> 8 | J11: =SUMIF(Orders!$B$2:$B$401,A11,Orders!$H$2:$H$401) -> 55426.68 | K11: =IFERROR(J11/I11,0) -> 6928.335
A12: 11 | B12: Ironclad Solutions | C12: Matthew Thomas | D12: matthew.thomas11@example.com | E12: Canada | F12: Toronto | G12: Consumer | H12: 2022-04-30 | I12: =COUNTIF(Orders!$B$2:$B$401,A12) -> 9 | J12: =SUMIF(Orders!$B$2:$B$401,A12,Orders!$H$2:$H$401) -> 37463.524 | K12: =IFERROR(J12/I12,0) -> 4162.6138
A13: 12 | B13: Nova Traders | C13: Charles Moore | D13: charles.moore12@example.com | E13: USA | F13: Chicago | G13: Small Business | H13: 2022-07-08 | I13: =COUNTIF(Orders!$B$2:$B$401,A13) -> 10 | J13: =SUMIF(Orders!$B$2:$B$401,A13,Orders!$H$2:$H$401) -> 38655.065 | K13: =IFERROR(J13/I13,0) -> 3865.5065
... A61: 60 | B61: Crestline Solutions | C61: Linda Rodriguez | D61: linda.rodriguez60@example.com | E61: Japan | F61: Tokyo | G61: Consumer | H61: 2022-03-16 | I61: =COUNTIF(Orders!$B$2:$B$401,A61) -> 9 | J61: =SUMIF(Orders!$B$2:$B$401,A61,Orders!$H$2:$H$401) -> 28706.987 | K61: =IFERROR(J61/I61,0) -> 3189.6652

Sheet Suppliers
A1: supplier id | B1: supplier name | C1: country | D1: lead time days | E1: rating | F1: Products Supplied | G1: Total Restock Qty | H1: Total Damaged Qty
A2: 1 | B2: Acme Manufacturing | C2: China | D2: 20 | E2: 3.4 | F2: =COUNTIF(Products!$D$2:$D$101,A2) -> 9 | G2: =SUMIFS(InventoryTransactions!$E$2:$E$351,InventoryTransactions!$H$2:$H$351,A2,InventoryTransactions!$D$2:$D$351,"Restock") -> 2613 | H2: =-SUMIFS(InventoryTransactions!$E$2:$E$351,InventoryTransactions!$H$2:$H$351,A2,InventoryTransactions!$D$2:$D$351,"Damaged") -> 83
A3: 2 | B3: Global Parts Ltd | C3: USA | D3: 25 | E3: 4.76 | F3: =COUNTIF(Products!$D$2:$D$101,A3) -> 11 | G3: =SUMIFS(InventoryTransactions!$E$2:$E$351,InventoryTransactions!$H$2:$H$351,A3,InventoryTransactions!$D$2:$D$351,"Restock") -> 3607 | H3: =-SUMIFS(InventoryTransactions!$E$2:$E$351,InventoryTransactions!$H$2:$H$351,A3,InventoryTransactions!$D$2:$D$351,"Damaged") -> 255
A4: 3 | B4: EastPoint Textiles | C4: Germany | D4: 10 | E4: 3.1 | F4: =COUNTIF(Products!$D$2:$D$101,A4) -> 3 | G4: =SUMIFS(InventoryTransactions!$E$2:$E$351,InventoryTransactions!$H$2:$H$351,A4,InventoryTransactions!$D$2:$D$351,"Restock") -> 334 | H4: =-SUMIFS(InventoryTransactions!$E$2:$E$351,InventoryTransactions!$H$2:$H$351,A4,InventoryTransactions!$D$2:$D$351,"Damaged") -> 45
A5: 4 | B5: Nordic Components | C5: Vietnam | D5: 19 | E5: 3.64 | F5: =COUNTIF(Products!$D$2:$D$101,A5) -> 7 | G5: =SUMIFS(InventoryTransactions!$E$2:$E$351,InventoryTransactions!$H$2:$H$351,A5,InventoryTransactions!$D$2:$D$351,"Restock") -> 3645 | H5: =-SUMIFS(InventoryTransactions!$E$2:$E$351,InventoryTransactions!$H$2:$H$351,A5,InventoryTransactions!$D$2:$D$351,"Damaged") -> 19
A6: 5 | B6: Pacific Rim Supply | C6: India | D6: 14 | E6: 4.35 | F6: =COUNTIF(Products!$D$2:$D$101,A6) -> 12 | G6: =SUMIFS(InventoryTransactions!$E$2:$E$351,InventoryTransactions!$H$2:$H$351,A6,InventoryTransactions!$D$2:$D$351,"Restock") -> 3359 | H6: =-SUMIFS(InventoryTransactions!$E$2:$E$351,InventoryTransactions!$H$2:$H$351,A6,InventoryTransactions!$D$2:$D$351,"Damaged") -> 67
